Workbook

Sheet Control
B2: FEBAN audit extract - control sheet
B3: Fill in the yellow cells, paste your recorded element IDs into 'Screen Map', then run modMain.RunExtract from the VBA editor.
B5: Legend
B6: Yellow fill | C6: You fill this in. The macro reads it and never overwrites it.
B7: Grey fill | C7: The macro writes here. Do not edit -- your edits are overwritten each run.
B8: Blue text | C8: A hardcoded input value.
B9: Cream fill | C9: An illustrative example, not live data. Delete or overwrite it.
B12: Setting | C12: Value | D12: Notes
B13: Expected SAP system ID (SID) | C13: PP2 | D13: The macro aborts if the attached session reports a different SID. Stops an audit extract being run against the wrong system.
B14: Expected SAP client | D14: Optional. Leave blank to skip the client check.
B15: Company code | C15: GBKM | D15: Per the audit request.
B16: Transaction for statement search | C16: FEBAN | D16: FEBAN is a POST-PROCESSING transaction, not a display-only one. See README, 'Why FEBAN is not read-only'. Set to FF.6 for a display-only statement view.
B17: House bank | D17: Optional FEBAN filter. Leave blank for all house banks.
B18: Account ID | D18: Optional FEBAN filter. Leave blank for all accounts.
B19: Download root folder | C19: C:\Users\eslucres\Documents\Audit GBKM | D19: Taken from recordings/Audit.vbs. Created if missing. One subfolder per month tab, e.g. ...\Audit GBKM\Sep 25.
B20: Confirming party name | C20: SANTANDER SCF | D20: If the largest ZP payment of the batch is to this party, it is a confirming (supply-chain-finance) payment and needs the extra hop to reach the supplier invoices. Matched on letters and digits, so 'SCF Santander' also matches, but 'SANTANDER UK PLC' does not.
B21: Run mode | C21: DRY RUN | D21: Both modes run the WHOLE chain and write the same files -- the exports are read-only on the SAP side, and the chain reads them back, so it cannot run without them. The only difference is where they land: DRY RUN puts everything under a '_dry run' subfolder of the download root, so a rehearsal is never mistaken for the evidence pack. Do one clean DRY RUN, read the Log, then switch.
B22: Amount match tolerance | C22: 0.01 | D22: Absolute currency tolerance when matching a sample amount to a statement line.
B23: Stop on first error | C23: YES | D23: YES halts the run on the first unrecognised screen. NO logs and continues to the next sample.
B24: Max seconds to wait per screen | C24: 60 | D24: Guards against an indefinite hang when SAP is slow.
B25: SAP date format | C25: DDMMYYYY | D25: How dates are typed into SAP. DDMMYYYY = 01092025, which is what recordings/Audit.vbs used and therefore what is known to work here. Also supported: DMY = 31.12.2025, DMY/ = 31/12/2025, MDY = 12/31/2025, YMD = 2025-12-31. Get this wrong and FEBAN silently searches the wrong period.
B26: Payment document type | C26: ZP | D26: Only documents of these types are taken from the Payment Usage list and fed to FBL1N. ZP is the SAP standard for a payment document. Takes a comma-separated list -- 'ZP, ZV, KZ' -- for batches paid outside the normal payment run. When nothing matches, the Log names the types the file actually held.
B27: Clearing line posting key | C27: 40 | D27: Step 4 opens the first line-item row with this posting key that also carries a clearing document. Blank means 'any row with a clearing document'.
B28: Payment usage document column | D28: Caption of the document-number column in the exported Payment Usage list, if the macro cannot find it. Open the first exported file and copy the heading exactly.
B29: Payment usage type column | D29: Caption of the document-type column in that same file. Without it every document is taken rather than only the ZP ones, and the Log says so.
B30: ZP list amount column | D30: Caption of the amount column in the exported FBL1N payment list. Leave blank -- the macro tries the caption, then the SAP technical name, then works it out from what the column contains, which is language-independent. Only fill this in if the Log says it picked the wrong one.
B31: ZP list vendor column | D31: Caption of the vendor-name column in that same file. Same rules.
B32: ZP list document column | D32: Caption of the document-number column in that same file. Same rules.
B33: Invoice document type | C33: KR | D33: The PDF is taken from the invoice, which is the KR document and carries a NEGATIVE amount. The list it is picked from holds several types at once -- ZP payments, KR invoices, SB statement documents -- so without this filter the largest row is usually a payment, not an invoice. Comparisons are on magnitude, so the negative sign does not matter.
B34: Invoice list amount column | D34: Santander SCF route only. Caption of the amount column in the exported list of invoices behind an SCF payment. Blank falls back to a built-in list of captions.
B35: Invoice list supplier column | D35: Caption of the supplier column in that same file.
B36: Invoice list document column | D36: Caption of the invoice-number column in that same file.
B37: Extra popup titles to allow | D37: Pipe-separated. The run stops on any modal popup it does not recognise rather than pressing Enter through it. The save dialog and the attachment list are identified by their contents, so language does not matter for those -- add a title here only if your system shows a popup the run does not expect.
B38: Operator name | D38: Written into the log for the audit trail.
B41: Progress (formulas over the Samples sheet)
B42: Samples in the sheet | C42: =COUNTA(Samples!A5:A1000)
B43: Included in the next run | C43: =COUNTIF(Samples!P5:P1000,"Yes")+COUNTBLANK(Samples!P5:P60)
B44: Excluded | C44: =COUNTIF(Samples!P5:P1000,"No")
B45: DONE -- invoice downloaded | C45: =COUNTIF(Samples!J5:J1000,"DONE")
B46: BLOCKED_FBL1N -- steps 8-9 not mapped yet | C46: =COUNTIF(Samples!J5:J1000,"BLOCKED_FBL1N")
...

Sheet Screen Map
B2: SAP element IDs
B3: Column F is what the macro reads. Column D says how much to trust it. recorded = came straight out of a recording in recordings/, so it should be right for this system. VERIFY = standard SAP, but no recording touched it. PREDICTED = written from standard SAP for steps 8-10, which no recording reaches at all -- put SAP on the screen in question and run modProbe.ProbeCurrentScreen to find out which of these hold, then correct them here. BLOCKED = genuinely unknown, and the run stops short of that stage and says so.
B5: Key | C5: What it is | D5: Source | E5: Required | F5: Element ID (the macro reads this)
B6: Step 1: FEBAN selection (a MODAL popup on this system, wnd[1])
B7: FEBAN.SelectionWindow | C7: Window the selection fields sit in. wnd[1] here, because FEBAN opens its selection as a popup rather than a full screen | D7: recorded | E7: Yes | F7: wnd[1]
B8: FEBAN.CompanyCode | C8: Company code | D8: recorded | E8: Yes | F8: wnd[1]/usr/ctxtSL_BUKRS-LOW
B9: FEBAN.StatementDateFrom | C9: Statement date, low | D9: recorded | E9: Yes | F9: wnd[1]/usr/ctxtSL_AZDAT-LOW
B10: FEBAN.StatementDateTo | C10: Statement date, high | D10: recorded | E10: Yes | F10: wnd[1]/usr/ctxtSL_AZDAT-HIGH
B11: FEBAN.ExecuteButton | C11: Execute, on the popup's own toolbar | D11: recorded | E11: Yes | F11: wnd[1]/tbar[0]/btn[8]
B12: FEBAN.PostExecuteButton | C12: Toolbar button pressed straight after Execute in all four recordings. Clear it to skip | D12: recorded | E12: No | F12: wnd[0]/tbar[1]/btn[14]
B13: FEBAN.HouseBank | C13: House bank filter. Not recorded; worth setting if the EUR account is out of scope. VERIFY | D13: VERIFY | E13: No | F13: wnd[1]/usr/ctxtSL_HBKID-LOW
B14: FEBAN.AccountId | C14: Account ID filter. VERIFY | D14: VERIFY | E14: No | F14: wnd[1]/usr/ctxtSL_HKTID-LOW
B15: Step 2: FEBAN result list
B16: FEBAN.ResultGrid | C16: ALV grid of statement items | D16: recorded | E16: Yes | F16: wnd[0]/shellcont/shell
B17: FEBAN.Col.Amount | C17: Amount column | D17: recorded | E17: Yes | F17: KWBTR
B18: FEBAN.Col.ValueDate | C18: Statement date column. Audit2.vbs double-clicked this by name, so it is a captured value | D18: recorded | E18: Yes | F18: AZDAT
B19: FEBAN.Col.Status | C19: Update-status column. The grid dump on PP2 shows no ESTAT -- VB1OK 'Update 1 OK' and VB2OK '2nd update OK' are what this release carries | D19: recorded | E19: No | F19: VB1OK
B20: FEBAN.Col.DocNumber | C20: FI document column. VERIFY | D20: VERIFY | E20: No | F20: BELNR
B21: FEBAN.Col.Reference | C21: Note-to-payee, logged beside each match as context. The grid dump shows no SGTXT; VWEZW is 'Payment Notes' and VGREF is 'Bank reference' | D21: recorded | E21: No | F21: VWEZW
B22: ALV export (confirmed in Audit2.vbs)
B23: Export.AlvToolbarButton | C23: Grid toolbar export function code | D23: recorded | E23: No | F23: &MB_EXPORT
B24: Export.AlvMenuItem | C24: Context-menu entry. &XXL, not &PC | D24: recorded | E24: No | F24: &XXL
B25: Export.AlvFormatRadio | C25: Radio for the format, if that popup appears. VERIFY | D25: VERIFY | E25: No
B26: Step 3: statement item detail
B27: Feban.Detail.DocNumber | C27: Posting Area 1 Doc. number field. F2 from here opens the FI document | D27: recorded | E27: Yes | F27: wnd[0]/usr/subSUB_MAIN:SAPLNEW_FEBA:4000/subSUB_APPLICATION:SAPLNEW_FEBA:2200/subAREA1:SAPLNEW_FEBA:2201/txtD2201_BELNR
B28: Step 4: FI document line items
B29: Doc.BsegGrid | C29: Line-item grid on the document overview | D29: recorded | E29: Yes | F29: wnd[0]/usr/cntlCTRL_CONTAINERBSEG/shellcont/shell
B30: Doc.Col.ClearingDoc | C30: Clearing-document column. Audit3 and Audit5 both double-clicked AUGBL; Audit.vbs used DMBTR and Audit2 PRCTR, which were just where the cursor sat | D30: recorded | E30: Yes | F30: AUGBL
B31: Doc.Col.PostingKey | C31: Posting-key column, so the macro can pick the key-40 line rather than whichever row the cursor lands on. VERIFY | D31: VERIFY | E31: No | F31: BSCHL
B32: Step 5: line-item detail
B33: Doc.ClearingDocField | C33: Clearing-document field. F2 from here opens the clearing document | D33: recorded | E33: Yes | F33: wnd[0]/usr/txtBSEG-AUGBL
B34: Doc.OverviewButton | C34: Document-overview button. F2 on the FBL1N list lands on the LINE ITEM, and Environment > Payment usage lives on the document -- this is the hop between them, pressed in N1.vbs. Only used when the usage menu is missing, so clearing it just skips the attempt | D34: recorded | E34: No | F34: wnd[0]/tbar[1]/btn[9]
B35: Step 6: Environment > Payment Usage
B36: PaymentUsage.Menu | C36: Menu path to the batch's payment documents. Confirmed in all four recordings | D36: recorded | E36: Yes | F36: wnd[0]/mbar/menu[5]/menu[3]
B37: PaymentUsage.ListAnchor | C37: An element that exists on that list, used only to confirm the menu landed. Clear it to skip the check | D37: recorded | E37: No | F37: wnd[0]/usr/chk[1,6]
B38: Step 7: classic list export (List > Save/Send > File)
B39: Export.ListMenu | C39: Menu path that opens the save-list dialog | D39: recorded | E39: Yes | F39: wnd[0]/mbar/menu[0]/menu[3]/menu[1]
B40: Export.FormatOkButton | C40: Confirm the file-format popup | D40: recorded | E40: Yes | F40: wnd[1]/tbar[0]/btn[0]
B41: Save.Path | C41: Directory field | D41: recorded | E41: Yes | F41: wnd[1]/usr/ctxtDY_PATH
B42: Save.FileName | C42: File name field. Confirmed in Audit2.vbs and Audit5.vbs | D42: recorded | E42: Yes | F42: wnd[1]/usr/ctxtDY_FILENAME
...

Sheet Samples
A2: Audit samples
A3: Extracted from the auditor's 'Paper Samples' sheet by scripts/extract_samples.py. Columns C and D are formulas, so correcting a payment date in column E re-derives the FEBAN statement-date range automatically.
A4: # | B4: Month tab | C4: Stmt date from | D4: Stmt date to | E4: Payment date | F4: Amount | G4: Name of party | H4: Payment reference | I4: Data flags (from the auditor's file) | J4: Status | K4: Bank stmt / FEBAN item | L4: FI document | M4: Vendor invoice(s) | N4: Files | O4: Message | P4: Include?
A5: 1 | B5: Sep 25 | C5: =IF($E5="","",DATE(YEAR($E5),MONTH($E5),1)) | D5: =IF($E5="","",EOMONTH($E5,0)) | E5: 45903 | F5: 8072447.4 | H5: ACH PYMTS - LCL BULK FNDG | I5: ref_whitespace_cleaned; no_named_beneficiary | P5: Yes
A6: 2 | B6: Sep 25 | C6: =IF($E6="","",DATE(YEAR($E6),MONTH($E6),1)) | D6: =IF($E6="","",EOMONTH($E6,0)) | E6: 45912 | F6: 2161788.2 | G6: DS SMITH LTD | H6: ISSUE CHAPS PAYMENT | I6: ref_whitespace_cleaned | P6: Yes
A7: 3 | B7: Sep 25 | C7: =IF($E7="","",DATE(YEAR($E7),MONTH($E7),1)) | D7: =IF($E7="","",EOMONTH($E7,0)) | E7: 45915 | F7: 5988033.6 | H7: ACH PYMTS - LCL BULK FNDG | I7: ref_whitespace_cleaned; no_named_beneficiary | P7: Yes
A8: 4 | B8: Sep 25 | C8: =IF($E8="","",DATE(YEAR($E8),MONTH($E8),1)) | D8: =IF($E8="","",EOMONTH($E8,0)) | E8: 45922 | F8: 2942842.5 | H8: ACH PYMTS - LCL BULK FNDG | I8: ref_whitespace_cleaned; no_named_beneficiary | P8: Yes
A9: 5 | B9: Sep 25 | C9: =IF($E9="","",DATE(YEAR($E9),MONTH($E9),1)) | D9: =IF($E9="","",EOMONTH($E9,0)) | E9: 45924 | F9: 8617262.9 | G9: DS Smith Paper Limited | H9: ISSUE CHAPS PAYMENT | I9: ref_whitespace_cleaned; party_whitespace_cleaned | P9: Yes
A10: 6 | B10: Sep 25 | C10: =IF($E10="","",DATE(YEAR($E10),MONTH($E10),1)) | D10: =IF($E10="","",EOMONTH($E10,0)) | E10: 45925 | F10: 2968313.2 | G10: DS Smith Paper Limited | H10: ISSUE CHAPS PAYMENT | I10: party_whitespace_cleaned | P10: Yes
A11: 7 | B11: Sep 25 | C11: =IF($E11="","",DATE(YEAR($E11),MONTH($E11),1)) | D11: =IF($E11="","",EOMONTH($E11,0)) | E11: 45930 | F11: 2450000 | G11: DS SMITH LTD | H11: ISSUE CHAPS PAYMENT | I11: ref_whitespace_cleaned; party_whitespace_cleaned | P11: Yes
A12: 8 | B12: Oct 25 | C12: =IF($E12="","",DATE(YEAR($E12),MONTH($E12),1)) | D12: =IF($E12="","",EOMONTH($E12,0)) | E12: 45931 | F12: 4483676.1 | G12: SANTANDER SCF | H12: ISSUE CHAPS PAYMENT | I12: ref_whitespace_cleaned; party_whitespace_cleaned | P12: Yes
A13: 9 | B13: Oct 25 | C13: =IF($E13="","",DATE(YEAR($E13),MONTH($E13),1)) | D13: =IF($E13="","",EOMONTH($E13,0)) | E13: 45933 | F13: 3412039 | H13: ACH PYMTS - LCL BULK FNDG | I13: ref_whitespace_cleaned; no_named_beneficiary | P13: Yes
A14: 10 | B14: Oct 25 | C14: =IF($E14="","",DATE(YEAR($E14),MONTH($E14),1)) | D14: =IF($E14="","",EOMONTH($E14,0)) | E14: 45943 | F14: 3385329.5 | H14: ACH PYMTS - LCL BULK FNDG | I14: ref_whitespace_cleaned; no_named_beneficiary | P14: Yes
A15: 11 | B15: Oct 25 | C15: =IF($E15="","",DATE(YEAR($E15),MONTH($E15),1)) | D15: =IF($E15="","",EOMONTH($E15,0)) | E15: 45950 | F15: 4898587.9 | H15: ACH PYMTS - LCL BULK FNDG | I15: ref_whitespace_cleaned; no_named_beneficiary | P15: Yes
A16: 12 | B16: Oct 25 | C16: =IF($E16="","",DATE(YEAR($E16),MONTH($E16),1)) | D16: =IF($E16="","",EOMONTH($E16,0)) | E16: 45954 | F16: 3480924.5 | G16: DS SMITH LTD | H16: ISSUE CHAPS PAYMENT | I16: date_stored_as_text; party_whitespace_cleaned | P16: Yes
A17: 13 | B17: Oct 25 | C17: =IF($E17="","",DATE(YEAR($E17),MONTH($E17),1)) | D17: =IF($E17="","",EOMONTH($E17,0)) | E17: 45957 | F17: 2614260 | G17: DS Smith Paper Limited | H17: ISSUE CHAPS PAYMENT | I17: party_whitespace_cleaned | P17: Yes
A18: 14 | B18: Oct 25 | C18: =IF($E18="","",DATE(YEAR($E18),MONTH($E18),1)) | D18: =IF($E18="","",EOMONTH($E18,0)) | E18: 45961 | F18: 2450000 | G18: DS SMITH LTD | H18: ISSUE CHAPS PAYMENT | I18: party_whitespace_cleaned | P18: Yes
A19: 15 | B19: Oct 25 | C19: =IF($E19="","",DATE(YEAR($E19),MONTH($E19),1)) | D19: =IF($E19="","",EOMONTH($E19,0)) | E19: 45961 | F19: 3317511.8 | G19: DS Smith Paper Limited | H19: ISSUE CHAPS PAYMENT | I19: party_whitespace_cleaned | P19: Yes
A20: 16 | B20: Nov 25 | C20: =IF($E20="","",DATE(YEAR($E20),MONTH($E20),1)) | D20: =IF($E20="","",EOMONTH($E20,0)) | E20: 45964 | F20: 3724798.3 | G20: SANTANDER SCF | H20: ISSUE CHAPS PAYMENT | P20: Yes
A21: 17 | B21: Nov 25 | C21: =IF($E21="","",DATE(YEAR($E21),MONTH($E21),1)) | D21: =IF($E21="","",EOMONTH($E21,0)) | E21: 45966 | F21: 5044035.1 | H21: ACH PYMTS - LCL BULK FNDG | I21: ref_whitespace_cleaned; no_named_beneficiary | P21: Yes
A22: 18 | B22: Nov 25 | C22: =IF($E22="","",DATE(YEAR($E22),MONTH($E22),1)) | D22: =IF($E22="","",EOMONTH($E22,0)) | E22: 45978 | F22: 5245536.5 | H22: ACH PYMTS - LCL BULK FNDG | I22: ref_whitespace_cleaned; no_named_beneficiary | P22: Yes
A23: 19 | B23: Nov 25 | C23: =IF($E23="","",DATE(YEAR($E23),MONTH($E23),1)) | D23: =IF($E23="","",EOMONTH($E23,0)) | E23: 45989 | F23: 4173936.7 | G23: DS Smith Paper Limited | H23: ISSUE CHAPS PAYMENT | I23: party_whitespace_cleaned | P23: Yes
A24: 20 | B24: Nov 25 | C24: =IF($E24="","",DATE(YEAR($E24),MONTH($E24),1)) | D24: =IF($E24="","",EOMONTH($E24,0)) | E24: 45989 | F24: 2450000 | G24: DS SMITH LTD | H24: ISSUE CHAPS PAYMENT | I24: date_stored_as_text; ref_whitespace_cleaned; party_whitespace_cleaned | P24: Yes
A25: 21 | B25: Dec 25 | C25: =IF($E25="","",DATE(YEAR($E25),MONTH($E25),1)) | D25: =IF($E25="","",EOMONTH($E25,0)) | E25: 46020 | F25: 2828677.7 | G25: DS Smith Paper Limited | H25: ISSUE CHAPS PAYMENT | I25: party_whitespace_cleaned | P25: Yes
A26: 22 | B26: Dec 25 | C26: =IF($E26="","",DATE(YEAR($E26),MONTH($E26),1)) | D26: =IF($E26="","",EOMONTH($E26,0)) | E26: 46022 | F26: 2450000 | G26: DS SMITH LTD | H26: ISSUE CHAPS PAYMENT | I26: ref_whitespace_cleaned; party_whitespace_cleaned | P26: Yes
A27: 23 | B27: Dec 25 | C27: =IF($E27="","",DATE(YEAR($E27),MONTH($E27),1)) | D27: =IF($E27="","",EOMONTH($E27,0)) | E27: 46022 | F27: 2233242 | G27: DS Smith Paper Limited | H27: ISSUE CHAPS PAYMENT | I27: party_whitespace_cleaned | P27: Yes
A28: 24 | B28: Jan 26 | C28: =IF($E28="","",DATE(YEAR($E28),MONTH($E28),1)) | D28: =IF($E28="","",EOMONTH($E28,0)) | E28: 46024 | F28: 3489078 | G28: SANTANDER SCF | H28: ISSUE CHAPS PAYMENT | I28: ref_whitespace_cleaned | P28: Yes
A29: 25 | B29: Jan 26 | C29: =IF($E29="","",DATE(YEAR($E29),MONTH($E29),1)) | D29: =IF($E29="","",EOMONTH($E29,0)) | E29: 46028 | F29: 4395299.2 | H29: ACH PYMTS - LCL BULK FNDG | I29: ref_whitespace_cleaned; no_named_beneficiary | P29: Yes
A30: 26 | B30: Jan 26 | C30: =IF($E30="","",DATE(YEAR($E30),MONTH($E30),1)) | D30: =IF($E30="","",EOMONTH($E30,0)) | E30: 46031 | F30: 8800991.4 | H30: ACH PYMTS - LCL BULK FNDG | I30: ref_whitespace_cleaned; no_named_beneficiary | P30: Yes
A31: 27 | B31: Jan 26 | C31: =IF($E31="","",DATE(YEAR($E31),MONTH($E31),1)) | D31: =IF($E31="","",EOMONTH($E31,0)) | E31: 46038 | F31: 6502110.7 | G31: DS SMITH LTD | H31: ISSUE CHAPS PAYMENT | I31: date_stored_as_text; ref_whitespace_cleaned; party_whitespace_cleaned | P31: Yes
A32: 28 | B32: Jan 26 | C32: =IF($E32="","",DATE(YEAR($E32),MONTH($E32),1)) | D32: =IF($E32="","",EOMONTH($E32,0)) | E32: 46051 | F32: 3463573.2 | G32: DS SMITH LTD | H32: ISSUE CHAPS PAYMENT | I32: ref_whitespace_cleaned; party_whitespace_cleaned | P32: Yes
A33: 29 | B33: Jan 26 | C33: =IF($E33="","",DATE(YEAR($E33),MONTH($E33),1)) | D33: =IF($E33="","",EOMONTH($E33,0)) | E33: 46052 | F33: 2450000 | G33: DS SMITH LTD | H33: ISSUE CHAPS PAYMENT | I33: ref_whitespace_cleaned; party_whitespace_cleaned | P33: Yes
A34: 30 | B34: Feb 26 | C34: =IF($E34="","",DATE(YEAR($E34),MONTH($E34),1)) | D34: =IF($E34="","",EOMONTH($E34,0)) | E34: 46055 | F34: 3679179.8 | G34: SANTANDER SCF | H34: ISSUE CHAPS PAYMENT | I34: ref_whitespace_cleaned | P34: Yes
A35: 31 | B35: Feb 26 | C35: =IF($E35="","",DATE(YEAR($E35),MONTH($E35),1)) | D35: =IF($E35="","",EOMONTH($E35,0)) | E35: 46057 | F35: 3674499.5 | H35: ACH PYMTS - LCL BULK FNDG | I35: ref_whitespace_cleaned; no_named_beneficiary | P35: Yes
A36: 32 | B36: Feb 26 | C36: =IF($E36="","",DATE(YEAR($E36),MONTH($E36),1)) | D36: =IF($E36="","",EOMONTH($E36,0)) | E36: 46080 | F36: 6558159.1 | G36: DS Smith Paper Limited | H36: ISSUE CHAPS PAYMENT | I36: party_whitespace_cleaned | P36: Yes
A37: 33 | B37: Feb 26 | C37: =IF($E37="","",DATE(YEAR($E37),MONTH($E37),1)) | D37: =IF($E37="","",EOMONTH($E37,0)) | E37: 46080 | F37: 2450000 | G37: DS SMITH LTD | H37: ISSUE CHAPS PAYMENT | I37: ref_whitespace_cleaned; party_whitespace_cleaned | P37: Yes
A38: 34 | B38: Mar 26 | C38: =IF($E38="","",DATE(YEAR($E38),MONTH($E38),1)) | D38: =IF($E38="","",EOMONTH($E38,0)) | E38: 46083 | F38: 3562528.9 | G38: SANTANDER SCF | H38: ISSUE CHAPS PAYMENT | I38: ref_whitespace_cleaned; party_whitespace_cleaned | P38: Yes
A39: 35 | B39: Mar 26 | C39: =IF($E39="","",DATE(YEAR($E39),MONTH($E39),1)) | D39: =IF($E39="","",EOMONTH($E39,0)) | E39: 46085 | F39: 8557737.2 | H39: ACH PYMTS - LCL BULK FNDG | I39: no_named_beneficiary | P39: Yes
A40: 36 | B40: Mar 26 | C40: =IF($E40="","",DATE(YEAR($E40),MONTH($E40),1)) | D40: =IF($E40="","",EOMONTH($E40,0)) | E40: 46093 | F40: 2301959.8 | H40: ACH PYMTS - LCL BULK FNDG | I40: no_named_beneficiary | P40: Yes
A41: 37 | B41: Mar 26 | C41: =IF($E41="","",DATE(YEAR($E41),MONTH($E41),1)) | D41: =IF($E41="","",EOMONTH($E41,0)) | E41: 46108 | F41: 5989486.5 | G41: DS Smith Paper Limited | H41: DS Smith Paper Limited | I41: ref_holds_a_party_name_not_a_transaction_description; party_whitespace_cleaned | P41: Yes
...

Sheet Log
A2: Audit trail
A3: Appended by the macro, one row per action, in DRY RUN as well as EXTRACT. Keep this sheet with the extract -- it is the record of who pulled what, from which system, and when.
A4: Timestamp | B4: Sample # | C4: SAP SID | D4: Client | E4: SAP user | F4: Transaction | G4: Action | H4: Detail | I4: Result | J4: File written

Sheet Data Issues
B2: Data-quality flags in the auditor's request
B3: Raised while reading 'Paper Samples'. Nothing here blocks the extract, but the starred rows are worth raising with the auditor before you send anything back.
B5: Flag | C5: Count | D5: Sample # | E5: What it means
B6: party_whitespace_cleaned | C6: 27 | D6: 5, 6, 7, 8, 12, 13, 14, 15, 19, 20, 21, 22, ... (+15 more) | E6: Leading, trailing or doubled spaces removed from the party name.
B7: ref_whitespace_cleaned | C7: 26 | D7: 1, 2, 3, 4, 5, 7, 8, 9, 10, 11, 17, 18, ... (+14 more) | E7: Leading or trailing spaces removed from the payment reference.
B8: no_named_beneficiary | C8: 18 | D8: 1, 3, 4, 9, 10, 11, 17, 18, 25, 26, 31, 35, ... (+6 more) | E8: The request shows '-' as the party. These are the lines the auditor's 'Payment to Supplier?' question actually turns on, since the bank statement alone does not name a payee.
B9: date_stored_as_text | C9: 3 | D9: 12, 20, 27 | E9: The payment date was typed as text, not a date. Normalised on extract; the auditor's own file still holds text.
B10: ref_holds_a_party_name_not_a_transaction_description | C10: 1 | D10: 37 | E10: The payment-reference cell contains a party name. Confirm the intended transaction description with the auditor before searching on it.
B11: ref_typo_corrected_from:ACH PYMTS - LCL BULK FNG | C11: 1 | D11: 52 | E11: Transaction description misspelt ('FNG' for 'FNDG'). Corrected on extract.
B13: Findings outside the sample rows
B14: * | C14: The auditor's month tabs already hold 55 pasted bank-statement screenshots, one per sample -- so the bank side of the evidence is done and the SAP side is what is missing.
B15: * | C15: 'Oct 25' holds 8 sample rows but only 7 screenshots, so one October line has no bank evidence attached. Worth confirming with the auditor which line.
B16: * | C16: One October screenshot is for account 12343649 / IBAN GB49CITI18500812343649 in EUR, where every other screenshot is account 12343657 / GB27CITI18500812343657 in GBP. Either a second account is in scope or a screenshot was mis-pasted.
B17: * | C17: Column G of 'Paper Samples', 'Payment to Supplier?', is blank on all 56 rows. That is the column this extract exists to let you answer.
